Workbook

Sheet Suivi
A1: Golfight - Suivi de projet
A2: Terminées : | B2: =COUNTIF(H5:H64,"Terminé")&" / "&COUNTA(B5:B64)&" ("&TEXT(IFERROR(COUNTIF(H5:H64,"Terminé")/COUNTA(B5:B64),0),"0%")&")" -> 8 / 26 (31%) | C2: En retard : | D2: =COUNTIFS(F5:F64,"<"&TODAY(),H5:H64,"<>Terminé",B5:B64,"<>") -> 0 | I2: Légende du Gantt : | J2: Terminé | L2: En cours | N2: À faire | P2: En retard | R2: Cette semaine
I3: S = séance cette semaine | J3: =IF(COUNTIFS(Listes!$F$2:$F$20,">="&J4,Listes!$F$2:$F$20,"<"&J4+7)>0,"S","") -> S | K3: =IF(COUNTIFS(Listes!$F$2:$F$20,">="&K4,Listes!$F$2:$F$20,"<"&K4+7)>0,"S","") -> S | L3: =IF(COUNTIFS(Listes!$F$2:$F$20,">="&L4,Listes!$F$2:$F$20,"<"&L4+7)>0,"S","") -> S | M3: =IF(COUNTIFS(Listes!$F$2:$F$20,">="&M4,Listes!$F$2:$F$20,"<"&M4+7)>0,"S","") -> S | N3: =IF(COUNTIFS(Listes!$F$2:$F$20,">="&N4,Listes!$F$2:$F$20,"<"&N4+7)>0,"S","") -> S | O3: =IF(COUNTIFS(Listes!$F$2:$F$20,">="&O4,Listes!$F$2:$F$20,"<"&O4+7)>0,"S","") -> S | P3: =IF(COUNTIFS(Listes!$F$2:$F$20,">="&P4,Listes!$F$2:$F$20,"<"&P4+7)>0,"S","") -> S | Q3: =IF(COUNTIFS(Listes!$F$2:$F$20,">="&Q4,Listes!$F$2:$F$20,"<"&Q4+7)>0,"S","") -> S | ... X3: =IF(COUNTIFS(Listes!$F$2:$F$20,">="&X4,Listes!$F$2:$F$20,"<"&X4+7)>0,"S","")
A4: N° | B4: Tâche | C4: Qui | D4: Sprint | E4: Début | F4: Fin | G4: Jours | H4: Statut | I4: Commentaire | J4: 46268 | K4: =J4+8 -> 46276 | L4: 46281 | M4: 46289 | N4: =M4+7 -> 46296 | O4: =N4+7 -> 46303 | P4: =O4+7 -> 46310 | Q4: 46330 | R4: 46331 | S4: 46351 | T4: =S4+2 -> 46353 | U4: =T4+11 -> 46364 | V4: =U4+1 -> 46365
A5: =IF(B5="","",ROW()-4) -> 1 | B5: Cahier des charges | C5: Tous | D5: Cadrage | E5: 46268 | F5: 46275 | G5: =IF(OR(E5="",F5=""),"",F5-E5+1) -> 8 | H5: Terminé
A6: =IF(B6="","",ROW()-4) -> 2 | B6: Architecture et répartition des tâches | C6: Tous | D6: Cadrage | E6: 46276 | F6: 46280 | G6: =IF(OR(E6="",F6=""),"",F6-E6+1) -> 5 | H6: Terminé
A7: =IF(B7="","",ROW()-4) -> 3 | B7: Test client / serveur avec socket | C7: Seth | D7: Sprint 1 | E7: 46281 | F7: 46288 | G7: =IF(OR(E7="",F7=""),"",F7-E7+1) -> 8 | H7: Terminé
A8: =IF(B8="","",ROW()-4) -> 4 | B8: Menu des réglages, résolution | C8: Sofiane | D8: Sprint 1 | E8: 46281 | F8: 46288 | G8: =IF(OR(E8="",F8=""),"",F8-E8+1) -> 8 | H8: Terminé
A9: =IF(B9="","",ROW()-4) -> 5 | B9: Physique : décélération et arrêt net | C9: Baptiste | D9: Sprint 1 | E9: 46281 | F9: 46288 | G9: =IF(OR(E9="",F9=""),"",F9-E9+1) -> 8 | H9: Terminé
A10: =IF(B10="","",ROW()-4) -> 6 | B10: Indicateur de vitesse et seuil de tir | C10: Baptiste | D10: Sprint 1 | E10: 46289 | F10: 46295 | G10: =IF(OR(E10="",F10=""),"",F10-E10+1) -> 7 | H10: Terminé
A11: =IF(B11="","",ROW()-4) -> 7 | B11: Communication TCP plusieurs clients | C11: Seth | D11: Sprint 1 | E11: 46289 | F11: 46296 | G11: =IF(OR(E11="",F11=""),"",F11-E11+1) -> 8 | H11: Terminé
A12: =IF(B12="","",ROW()-4) -> 8 | B12: Déploiement sur Render | C12: Sofiane | D12: Sprint 1 | E12: 46296 | F12: 46302 | G12: =IF(OR(E12="",F12=""),"",F12-E12+1) -> 7 | H12: Terminé
A13: =IF(B13="","",ROW()-4) -> 9 | B13: Spécification (spec.md) | C13: Seth | D13: Sprint 2 | E13: 46303 | F13: 46310 | G13: =IF(OR(E13="",F13=""),"",F13-E13+1) -> 8 | H13: En cours | I13: À relire par l'équipe
A14: =IF(B14="","",ROW()-4) -> 10 | B14: Pseudo et liste des joueurs connectés | C14: Seth | D14: Sprint 2 | E14: 46303 | F14: 46310 | G14: =IF(OR(E14="",F14=""),"",F14-E14+1) -> 8 | H14: À faire
A15: =IF(B15="","",ROW()-4) -> 11 | B15: Invitations (accepter / refuser) | C15: Seth | D15: Sprint 2 | E15: 46303 | F15: 46310 | G15: =IF(OR(E15="",F15=""),"",F15-E15+1) -> 8 | H15: À faire
A16: =IF(B16="","",ROW()-4) -> 12 | B16: Partie à 2 joueurs synchronisée | C16: Seth | D16: Sprint 2 | E16: 46303 | F16: 46310 | G16: =IF(OR(E16="",F16=""),"",F16-E16+1) -> 8 | H16: À faire
A17: =IF(B17="","",ROW()-4) -> 13 | B17: Tir simultané avec seuil de vitesse | C17: Baptiste | D17: Sprint 2 | E17: 46303 | F17: 46310 | G17: =IF(OR(E17="",F17=""),"",F17-E17+1) -> 8 | H17: En cours
A18: =IF(B18="","",ROW()-4) -> 14 | B18: Mode solo dans le navigateur | C18: Baptiste | D18: Sprint 2 | E18: 46303 | F18: 46310 | G18: =IF(OR(E18="",F18=""),"",F18-E18+1) -> 8 | H18: En cours
A19: =IF(B19="","",ROW()-4) -> 15 | B19: Menu principal et écrans web (Django) | C19: Sofiane | D19: Sprint 2 | E19: 46303 | F19: 46310 | G19: =IF(OR(E19="",F19=""),"",F19-E19+1) -> 8 | H19: En cours
A20: =IF(B20="","",ROW()-4) -> 16 | B20: Lobby : choix de la carte, bouton Prêt | C20: Sofiane | D20: Sprint 3 | E20: 46310 | F20: 46330 | G20: =IF(OR(E20="",F20=""),"",F20-E20+1) -> 21 | H20: À faire
A21: =IF(B21="","",ROW()-4) -> 17 | B21: Placement inversé (balle et trou) | C21: Baptiste | D21: Sprint 3 | E21: 46310 | F21: 46331 | G21: =IF(OR(E21="",F21=""),"",F21-E21+1) -> 22 | H21: À faire
A22: =IF(B22="","",ROW()-4) -> 18 | B22: Vérification des placements (serveur) | C22: Seth | D22: Sprint 3 | E22: 46310 | F22: 46331 | G22: =IF(OR(E22="",F22=""),"",F22-E22+1) -> 22 | H22: À faire
A23: =IF(B23="","",ROW()-4) -> 19 | B23: Collision entre les deux balles | C23: Baptiste | D23: Sprint 3 | E23: 46310 | F23: 46331 | G23: =IF(OR(E23="",F23=""),"",F23-E23+1) -> 22 | H23: À faire
A24: =IF(B24="","",ROW()-4) -> 20 | B24: Fin de manche, rejouer / quitter, score | C24: Seth | D24: Sprint 3 | E24: 46310 | F24: 46331 | G24: =IF(OR(E24="",F24=""),"",F24-E24+1) -> 22 | H24: À faire
A25: =IF(B25="","",ROW()-4) -> 21 | B25: Cartes avec obstacles | C25: Baptiste | D25: Sprint 3 | E25: 46310 | F25: 46331 | G25: =IF(OR(E25="",F25=""),"",F25-E25+1) -> 22 | H25: À faire
... A27: =IF(B27="","",ROW()-4) -> 23 | B27: Déconnexions | C27: Seth | D27: Finition | E27: 46331 | F27: 46350 | G27: =IF(OR(E27="",F27=""),"",F27-E27+1) -> 20 | H27: À faire
A28: =IF(B28="","",ROW()-4) -> 24 | B28: Bonus : éditeur de cartes, particules, transitions | C28: Tous | D28: Finition | E28: 46331 | F28: 46350 | G28: =IF(OR(E28="",F28=""),"",F28-E28+1) -> 20 | H28: À faire | I28: Si on a le temps
A29: =IF(B29="","",ROW()-4) -> 25 | B29: Tests et correction des bugs | C29: Tous | D29: Tests | E29: 46351 | F29: 46358 | G29: =IF(OR(E29="",F29=""),"",F29-E29+1) -> 8 | H29: À faire
A30: =IF(B30="","",ROW()-4) -> 26 | B30: Préparer la présentation | C30: Tous | D30: Présentation | E30: 46353 | F30: 46365 | G30: =IF(OR(E30="",F30=""),"",F30-E30+1) -> 13 | H30: À faire
A31: =IF(B31="","",ROW()-4) | G31: =IF(OR(E31="",F31=""),"",F31-E31+1)
A32: =IF(B32="","",ROW()-4) | G32: =IF(OR(E32="",F32=""),"",F32-E32+1)
A33: =IF(B33="","",ROW()-4) | G33: =IF(OR(E33="",F33=""),"",F33-E33+1)
A34: =IF(B34="","",ROW()-4) | G34: =IF(OR(E34="",F34=""),"",F34-E34+1)
A35: =IF(B35="","",ROW()-4) | G35: =IF(OR(E35="",F35=""),"",F35-E35+1)
A36: =IF(B36="","",ROW()-4) | G36: =IF(OR(E36="",F36=""),"",F36-E36+1)
A37: =IF(B37="","",ROW()-4) | G37: =IF(OR(E37="",F37=""),"",F37-E37+1)
A38: =IF(B38="","",ROW()-4) | G38: =IF(OR(E38="",F38=""),"",F38-E38+1)
A39: =IF(B39="","",ROW()-4) | G39: =IF(OR(E39="",F39=""),"",F39-E39+1)
A40: =IF(B40="","",ROW()-4) | G40: =IF(OR(E40="",F40=""),"",F40-E40+1)
A41: =IF(B41="","",ROW()-4) | G41: =IF(OR(E41="",F41=""),"",F41-E41+1)
...

Sheet Listes
A1: Statut | B1: Membre | C1: Sprint | E1: Séance | F1: Date | G1: Objectif
A2: À faire | B2: Seth | C2: Cadrage | E2: 1 | F2: 46268 | G2: Cadrage, cahier des charges
A3: En cours | B3: Baptiste | C3: Sprint 1 | E3: 2 | F3: 46276 | G3: Architecture, répartition des tâches
A4: Terminé | B4: Sofiane | C4: Sprint 2 | E4: 3 | F4: 46281 | G4: Sprint 1.1
A5: Bloqué | B5: Tous | C5: Sprint 3 | E5: 4 | F5: 46289 | G5: Sprint 1.2
C6: Finition | E6: 5 | F6: 46296 | G6: Revue Sprint 1
C7: Tests | E7: 6 | F7: 46303 | G7: Sprint 2
C8: Présentation | E8: 7 | F8: 46310 | G8: Revue Sprint 2
E9: 8 | F9: 46330 | G9: Sprint 3
E10: 9 | F10: 46331 | G10: Finition
E11: 10 | F11: 46351 | G11: Tests et corrections
E12: 11 | F12: 46353 | G12: Tests et corrections
E13: 12 | F13: 46365 | G13: Présentation finale
A22: Vous pouvez ajouter des valeurs sous chaque liste (jusqu'à la ligne 20).
